2016-12-16 16:15:18,900 - aps - INFO - CURRENT KEY:10
2016-12-16 16:15:18,911 - aps - ERROR - Could not connect to server and get key.
2016-12-16 16:15:18,913 - aps - ERROR - Could not connect to server and get configuration.
Traceback (most recent call last):
  File "/usr/lib/python3.5/site-packages/requests/packages/urllib3/connection.py", line 142, in _new_conn
    (self.host, self.port), self.timeout, **extra_kw)
  File "/usr/lib/python3.5/site-packages/requests/packages/urllib3/util/connection.py", line 91, in create_connection
    raise err
  File "/usr/lib/python3.5/site-packages/requests/packages/urllib3/util/connection.py", line 81, in create_connection
    sock.connect(sa)
ConnectionRefusedError: [Errno 111] Connection refused

During handling of the above exception, another exception occurred:

Traceback (most recent call last):
  File "/usr/lib/python3.5/site-packages/requests/packages/urllib3/connectionpool.py", line 578, in urlopen
    chunked=chunked)
  File "/usr/lib/python3.5/site-packages/requests/packages/urllib3/connectionpool.py", line 362, in _make_request
    conn.request(method, url, **httplib_request_kw)
  File "/usr/lib64/python3.5/http/client.py", line 1106, in request
    self._send_request(method, url, body, headers)
  File "/usr/lib64/python3.5/http/client.py", line 1151, in _send_request
    self.endheaders(body)
  File "/usr/lib64/python3.5/http/client.py", line 1102, in endheaders
    self._send_output(message_body)
  File "/usr/lib64/python3.5/http/client.py", line 934, in _send_output
    self.send(msg)
  File "/usr/lib64/python3.5/http/client.py", line 877, in send
    self.connect()
  File "/usr/lib/python3.5/site-packages/requests/packages/urllib3/connection.py", line 167, in connect
    conn = self._new_conn()
  File "/usr/lib/python3.5/site-packages/requests/packages/urllib3/connection.py", line 151, in _new_conn
    self, "Failed to establish a new connection: %s" % e)
requests.packages.urllib3.exceptions.NewConnectionError: <requests.packages.urllib3.connection.HTTPConnection object at 0x7f8b601b2748>: Failed to establish a new connection: [Errno 111] Connection refused

During handling of the above exception, another exception occurred:

Traceback (most recent call last):
  File "/usr/lib/python3.5/site-packages/requests/adapters.py", line 403, in send
    timeout=timeout
  File "/usr/lib/python3.5/site-packages/requests/packages/urllib3/connectionpool.py", line 623, in urlopen
    _stacktrace=sys.exc_info()[2])
  File "/usr/lib/python3.5/site-packages/requests/packages/urllib3/util/retry.py", line 281, in increment
    raise MaxRetryError(_pool, url, error or ResponseError(cause))
requests.packages.urllib3.exceptions.MaxRetryError: HTTPConnectionPool(host='127.0.0.1', port=13000): Max retries exceeded with url: /aps/client_configuration (Caused by NewConnectionError('<requests.packages.urllib3.connection.HTTPConnection object at 0x7f8b601b2748>: Failed to establish a new connection: [Errno 111] Connection refused',))

During handling of the above exception, another exception occurred:

Traceback (most recent call last):
  File "/home/mc/PycharmProjects/Inzynierka/configuration_handlers/client_conifguration_handler.py", line 16, in get_client_configuration_from_server
    response = requests.post(url, data=json.dumps(payload), headers=headers)
  File "/usr/lib/python3.5/site-packages/requests/api.py", line 111, in post
    return request('post', url, data=data, json=json, **kwargs)
  File "/usr/lib/python3.5/site-packages/requests/api.py", line 57, in request
    return session.request(method=method, url=url, **kwargs)
  File "/usr/lib/python3.5/site-packages/requests/sessions.py", line 475, in request
    resp = self.send(prep, **send_kwargs)
  File "/usr/lib/python3.5/site-packages/requests/sessions.py", line 585, in send
    r = adapter.send(request, **kwargs)
  File "/usr/lib/python3.5/site-packages/requests/adapters.py", line 467, in send
    raise ConnectionError(e, request=request)
requests.exceptions.ConnectionError: HTTPConnectionPool(host='127.0.0.1', port=13000): Max retries exceeded with url: /aps/client_configuration (Caused by NewConnectionError('<requests.packages.urllib3.connection.HTTPConnection object at 0x7f8b601b2748>: Failed to establish a new connection: [Errno 111] Connection refused',))
2016-12-16 16:15:18,919 - aps - INFO - Configuration is not set by server
2016-12-16 16:15:23,924 - aps - ERROR - Could not connect to server and get configuration.
Traceback (most recent call last):
  File "/usr/lib/python3.5/site-packages/requests/packages/urllib3/connection.py", line 142, in _new_conn
    (self.host, self.port), self.timeout, **extra_kw)
  File "/usr/lib/python3.5/site-packages/requests/packages/urllib3/util/connection.py", line 91, in create_connection
    raise err
  File "/usr/lib/python3.5/site-packages/requests/packages/urllib3/util/connection.py", line 81, in create_connection
    sock.connect(sa)
ConnectionRefusedError: [Errno 111] Connection refused

During handling of the above exception, another exception occurred:

Traceback (most recent call last):
  File "/usr/lib/python3.5/site-packages/requests/packages/urllib3/connectionpool.py", line 578, in urlopen
    chunked=chunked)
  File "/usr/lib/python3.5/site-packages/requests/packages/urllib3/connectionpool.py", line 362, in _make_request
    conn.request(method, url, **httplib_request_kw)
  File "/usr/lib64/python3.5/http/client.py", line 1106, in request
    self._send_request(method, url, body, headers)
  File "/usr/lib64/python3.5/http/client.py", line 1151, in _send_request
    self.endheaders(body)
  File "/usr/lib64/python3.5/http/client.py", line 1102, in endheaders
    self._send_output(message_body)
  File "/usr/lib64/python3.5/http/client.py", line 934, in _send_output
    self.send(msg)
  File "/usr/lib64/python3.5/http/client.py", line 877, in send
    self.connect()
  File "/usr/lib/python3.5/site-packages/requests/packages/urllib3/connection.py", line 167, in connect
    conn = self._new_conn()
  File "/usr/lib/python3.5/site-packages/requests/packages/urllib3/connection.py", line 151, in _new_conn
    self, "Failed to establish a new connection: %s" % e)
requests.packages.urllib3.exceptions.NewConnectionError: <requests.packages.urllib3.connection.HTTPConnection object at 0x7f8b5fcad0f0>: Failed to establish a new connection: [Errno 111] Connection refused

During handling of the above exception, another exception occurred:

Traceback (most recent call last):
  File "/usr/lib/python3.5/site-packages/requests/adapters.py", line 403, in send
    timeout=timeout
  File "/usr/lib/python3.5/site-packages/requests/packages/urllib3/connectionpool.py", line 623, in urlopen
    _stacktrace=sys.exc_info()[2])
  File "/usr/lib/python3.5/site-packages/requests/packages/urllib3/util/retry.py", line 281, in increment
    raise MaxRetryError(_pool, url, error or ResponseError(cause))
requests.packages.urllib3.exceptions.MaxRetryError: HTTPConnectionPool(host='127.0.0.1', port=13000): Max retries exceeded with url: /aps/client_configuration (Caused by NewConnectionError('<requests.packages.urllib3.connection.HTTPConnection object at 0x7f8b5fcad0f0>: Failed to establish a new connection: [Errno 111] Connection refused',))

During handling of the above exception, another exception occurred:

Traceback (most recent call last):
  File "/home/mc/PycharmProjects/Inzynierka/configuration_handlers/client_conifguration_handler.py", line 16, in get_client_configuration_from_server
    response = requests.post(url, data=json.dumps(payload), headers=headers)
  File "/usr/lib/python3.5/site-packages/requests/api.py", line 111, in post
    return request('post', url, data=data, json=json, **kwargs)
  File "/usr/lib/python3.5/site-packages/requests/api.py", line 57, in request
    return session.request(method=method, url=url, **kwargs)
  File "/usr/lib/python3.5/site-packages/requests/sessions.py", line 475, in request
    resp = self.send(prep, **send_kwargs)
  File "/usr/lib/python3.5/site-packages/requests/sessions.py", line 585, in send
    r = adapter.send(request, **kwargs)
  File "/usr/lib/python3.5/site-packages/requests/adapters.py", line 467, in send
    raise ConnectionError(e, request=request)
requests.exceptions.ConnectionError: HTTPConnectionPool(host='127.0.0.1', port=13000): Max retries exceeded with url: /aps/client_configuration (Caused by NewConnectionError('<requests.packages.urllib3.connection.HTTPConnection object at 0x7f8b5fcad0f0>: Failed to establish a new connection: [Errno 111] Connection refused',))
2016-12-16 16:15:23,926 - aps - INFO - Configuration is not set by server
2016-12-16 16:15:28,932 - aps - ERROR - Could not connect to server and get configuration.
Traceback (most recent call last):
  File "/usr/lib/python3.5/site-packages/requests/packages/urllib3/connection.py", line 142, in _new_conn
    (self.host, self.port), self.timeout, **extra_kw)
  File "/usr/lib/python3.5/site-packages/requests/packages/urllib3/util/connection.py", line 91, in create_connection
    raise err
  File "/usr/lib/python3.5/site-packages/requests/packages/urllib3/util/connection.py", line 81, in create_connection
    sock.connect(sa)
ConnectionRefusedError: [Errno 111] Connection refused

During handling of the above exception, another exception occurred:

Traceback (most recent call last):
  File "/usr/lib/python3.5/site-packages/requests/packages/urllib3/connectionpool.py", line 578, in urlopen
    chunked=chunked)
  File "/usr/lib/python3.5/site-packages/requests/packages/urllib3/connectionpool.py", line 362, in _make_request
    conn.request(method, url, **httplib_request_kw)
  File "/usr/lib64/python3.5/http/client.py", line 1106, in request
    self._send_request(method, url, body, headers)
  File "/usr/lib64/python3.5/http/client.py", line 1151, in _send_request
    self.endheaders(body)
  File "/usr/lib64/python3.5/http/client.py", line 1102, in endheaders
    self._send_output(message_body)
  File "/usr/lib64/python3.5/http/client.py", line 934, in _send_output
    self.send(msg)
  File "/usr/lib64/python3.5/http/client.py", line 877, in send
    self.connect()
  File "/usr/lib/python3.5/site-packages/requests/packages/urllib3/connection.py", line 167, in connect
    conn = self._new_conn()
  File "/usr/lib/python3.5/site-packages/requests/packages/urllib3/connection.py", line 151, in _new_conn
    self, "Failed to establish a new connection: %s" % e)
requests.packages.urllib3.exceptions.NewConnectionError: <requests.packages.urllib3.connection.HTTPConnection object at 0x7f8b5fcad7f0>: Failed to establish a new connection: [Errno 111] Connection refused

During handling of the above exception, another exception occurred:

Traceback (most recent call last):
  File "/usr/lib/python3.5/site-packages/requests/adapters.py", line 403, in send
    timeout=timeout
  File "/usr/lib/python3.5/site-packages/requests/packages/urllib3/connectionpool.py", line 623, in urlopen
    _stacktrace=sys.exc_info()[2])
  File "/usr/lib/python3.5/site-packages/requests/packages/urllib3/util/retry.py", line 281, in increment
    raise MaxRetryError(_pool, url, error or ResponseError(cause))
requests.packages.urllib3.exceptions.MaxRetryError: HTTPConnectionPool(host='127.0.0.1', port=13000): Max retries exceeded with url: /aps/client_configuration (Caused by NewConnectionError('<requests.packages.urllib3.connection.HTTPConnection object at 0x7f8b5fcad7f0>: Failed to establish a new connection: [Errno 111] Connection refused',))

During handling of the above exception, another exception occurred:

Traceback (most recent call last):
  File "/home/mc/PycharmProjects/Inzynierka/configuration_handlers/client_conifguration_handler.py", line 16, in get_client_configuration_from_server
    response = requests.post(url, data=json.dumps(payload), headers=headers)
  File "/usr/lib/python3.5/site-packages/requests/api.py", line 111, in post
    return request('post', url, data=data, json=json, **kwargs)
  File "/usr/lib/python3.5/site-packages/requests/api.py", line 57, in request
    return session.request(method=method, url=url, **kwargs)
  File "/usr/lib/python3.5/site-packages/requests/sessions.py", line 475, in request
    resp = self.send(prep, **send_kwargs)
  File "/usr/lib/python3.5/site-packages/requests/sessions.py", line 585, in send
    r = adapter.send(request, **kwargs)
  File "/usr/lib/python3.5/site-packages/requests/adapters.py", line 467, in send
    raise ConnectionError(e, request=request)
requests.exceptions.ConnectionError: HTTPConnectionPool(host='127.0.0.1', port=13000): Max retries exceeded with url: /aps/client_configuration (Caused by NewConnectionError('<requests.packages.urllib3.connection.HTTPConnection object at 0x7f8b5fcad7f0>: Failed to establish a new connection: [Errno 111] Connection refused',))
2016-12-16 16:15:28,933 - aps - INFO - Configuration is not set by server
2016-12-16 16:15:33,940 - aps - ERROR - Could not connect to server and get configuration.
Traceback (most recent call last):
  File "/usr/lib/python3.5/site-packages/requests/packages/urllib3/connection.py", line 142, in _new_conn
    (self.host, self.port), self.timeout, **extra_kw)
  File "/usr/lib/python3.5/site-packages/requests/packages/urllib3/util/connection.py", line 91, in create_connection
    raise err
  File "/usr/lib/python3.5/site-packages/requests/packages/urllib3/util/connection.py", line 81, in create_connection
    sock.connect(sa)
ConnectionRefusedError: [Errno 111] Connection refused

During handling of the above exception, another exception occurred:

Traceback (most recent call last):
  File "/usr/lib/python3.5/site-packages/requests/packages/urllib3/connectionpool.py", line 578, in urlopen
    chunked=chunked)
  File "/usr/lib/python3.5/site-packages/requests/packages/urllib3/connectionpool.py", line 362, in _make_request
    conn.request(method, url, **httplib_request_kw)
  File "/usr/lib64/python3.5/http/client.py", line 1106, in request
    self._send_request(method, url, body, headers)
  File "/usr/lib64/python3.5/http/client.py", line 1151, in _send_request
    self.endheaders(body)
  File "/usr/lib64/python3.5/http/client.py", line 1102, in endheaders
    self._send_output(message_body)
  File "/usr/lib64/python3.5/http/client.py", line 934, in _send_output
    self.send(msg)
  File "/usr/lib64/python3.5/http/client.py", line 877, in send
    self.connect()
  File "/usr/lib/python3.5/site-packages/requests/packages/urllib3/connection.py", line 167, in connect
    conn = self._new_conn()
  File "/usr/lib/python3.5/site-packages/requests/packages/urllib3/connection.py", line 151, in _new_conn
    self, "Failed to establish a new connection: %s" % e)
requests.packages.urllib3.exceptions.NewConnectionError: <requests.packages.urllib3.connection.HTTPConnection object at 0x7f8b5fcadef0>: Failed to establish a new connection: [Errno 111] Connection refused

During handling of the above exception, another exception occurred:

Traceback (most recent call last):
  File "/usr/lib/python3.5/site-packages/requests/adapters.py", line 403, in send
    timeout=timeout
  File "/usr/lib/python3.5/site-packages/requests/packages/urllib3/connectionpool.py", line 623, in urlopen
    _stacktrace=sys.exc_info()[2])
  File "/usr/lib/python3.5/site-packages/requests/packages/urllib3/util/retry.py", line 281, in increment
    raise MaxRetryError(_pool, url, error or ResponseError(cause))
requests.packages.urllib3.exceptions.MaxRetryError: HTTPConnectionPool(host='127.0.0.1', port=13000): Max retries exceeded with url: /aps/client_configuration (Caused by NewConnectionError('<requests.packages.urllib3.connection.HTTPConnection object at 0x7f8b5fcadef0>: Failed to establish a new connection: [Errno 111] Connection refused',))

During handling of the above exception, another exception occurred:

Traceback (most recent call last):
  File "/home/mc/PycharmProjects/Inzynierka/configuration_handlers/client_conifguration_handler.py", line 16, in get_client_configuration_from_server
    response = requests.post(url, data=json.dumps(payload), headers=headers)
  File "/usr/lib/python3.5/site-packages/requests/api.py", line 111, in post
    return request('post', url, data=data, json=json, **kwargs)
  File "/usr/lib/python3.5/site-packages/requests/api.py", line 57, in request
    return session.request(method=method, url=url, **kwargs)
  File "/usr/lib/python3.5/site-packages/requests/sessions.py", line 475, in request
    resp = self.send(prep, **send_kwargs)
  File "/usr/lib/python3.5/site-packages/requests/sessions.py", line 585, in send
    r = adapter.send(request, **kwargs)
  File "/usr/lib/python3.5/site-packages/requests/adapters.py", line 467, in send
    raise ConnectionError(e, request=request)
requests.exceptions.ConnectionError: HTTPConnectionPool(host='127.0.0.1', port=13000): Max retries exceeded with url: /aps/client_configuration (Caused by NewConnectionError('<requests.packages.urllib3.connection.HTTPConnection object at 0x7f8b5fcadef0>: Failed to establish a new connection: [Errno 111] Connection refused',))
2016-12-16 16:15:33,940 - aps - INFO - Configuration is not set by server
2016-12-16 16:15:38,947 - aps - ERROR - Could not connect to server and get configuration.
Traceback (most recent call last):
  File "/usr/lib/python3.5/site-packages/requests/packages/urllib3/connection.py", line 142, in _new_conn
    (self.host, self.port), self.timeout, **extra_kw)
  File "/usr/lib/python3.5/site-packages/requests/packages/urllib3/util/connection.py", line 91, in create_connection
    raise err
  File "/usr/lib/python3.5/site-packages/requests/packages/urllib3/util/connection.py", line 81, in create_connection
    sock.connect(sa)
ConnectionRefusedError: [Errno 111] Connection refused

During handling of the above exception, another exception occurred:

Traceback (most recent call last):
  File "/usr/lib/python3.5/site-packages/requests/packages/urllib3/connectionpool.py", line 578, in urlopen
    chunked=chunked)
  File "/usr/lib/python3.5/site-packages/requests/packages/urllib3/connectionpool.py", line 362, in _make_request
    conn.request(method, url, **httplib_request_kw)
  File "/usr/lib64/python3.5/http/client.py", line 1106, in request
    self._send_request(method, url, body, headers)
  File "/usr/lib64/python3.5/http/client.py", line 1151, in _send_request
    self.endheaders(body)
  File "/usr/lib64/python3.5/http/client.py", line 1102, in endheaders
    self._send_output(message_body)
  File "/usr/lib64/python3.5/http/client.py", line 934, in _send_output
    self.send(msg)
  File "/usr/lib64/python3.5/http/client.py", line 877, in send
    self.connect()
  File "/usr/lib/python3.5/site-packages/requests/packages/urllib3/connection.py", line 167, in connect
    conn = self._new_conn()
  File "/usr/lib/python3.5/site-packages/requests/packages/urllib3/connection.py", line 151, in _new_conn
    self, "Failed to establish a new connection: %s" % e)
requests.packages.urllib3.exceptions.NewConnectionError: <requests.packages.urllib3.connection.HTTPConnection object at 0x7f8b5fcb4630>: Failed to establish a new connection: [Errno 111] Connection refused

During handling of the above exception, another exception occurred:

Traceback (most recent call last):
  File "/usr/lib/python3.5/site-packages/requests/adapters.py", line 403, in send
    timeout=timeout
  File "/usr/lib/python3.5/site-packages/requests/packages/urllib3/connectionpool.py", line 623, in urlopen
    _stacktrace=sys.exc_info()[2])
  File "/usr/lib/python3.5/site-packages/requests/packages/urllib3/util/retry.py", line 281, in increment
    raise MaxRetryError(_pool, url, error or ResponseError(cause))
requests.packages.urllib3.exceptions.MaxRetryError: HTTPConnectionPool(host='127.0.0.1', port=13000): Max retries exceeded with url: /aps/client_configuration (Caused by NewConnectionError('<requests.packages.urllib3.connection.HTTPConnection object at 0x7f8b5fcb4630>: Failed to establish a new connection: [Errno 111] Connection refused',))

During handling of the above exception, another exception occurred:

Traceback (most recent call last):
  File "/home/mc/PycharmProjects/Inzynierka/configuration_handlers/client_conifguration_handler.py", line 16, in get_client_configuration_from_server
    response = requests.post(url, data=json.dumps(payload), headers=headers)
  File "/usr/lib/python3.5/site-packages/requests/api.py", line 111, in post
    return request('post', url, data=data, json=json, **kwargs)
  File "/usr/lib/python3.5/site-packages/requests/api.py", line 57, in request
    return session.request(method=method, url=url, **kwargs)
  File "/usr/lib/python3.5/site-packages/requests/sessions.py", line 475, in request
    resp = self.send(prep, **send_kwargs)
  File "/usr/lib/python3.5/site-packages/requests/sessions.py", line 585, in send
    r = adapter.send(request, **kwargs)
  File "/usr/lib/python3.5/site-packages/requests/adapters.py", line 467, in send
    raise ConnectionError(e, request=request)
requests.exceptions.ConnectionError: HTTPConnectionPool(host='127.0.0.1', port=13000): Max retries exceeded with url: /aps/client_configuration (Caused by NewConnectionError('<requests.packages.urllib3.connection.HTTPConnection object at 0x7f8b5fcb4630>: Failed to establish a new connection: [Errno 111] Connection refused',))
2016-12-16 16:15:38,947 - aps - INFO - Configuration is not set by server
